Workbook

Sheet 3-statement model
C2: ="Financial Statement Model for "&D5 -> Financial Statement Model for Apple
C3: $ and shares in millions, except per share data
C5: Company name | D5: Apple
C6: Ticker | D6: AAPL
C7: Circ break 1=off, 0=on | D7: 1
C8: Latest closing share price
C9: Latest closing share price date
C10: Latest fiscal year end date | D10: 43372
C11: Shares outstanding (millions) | D11: 4745398
C12: Select an operating scenario: | D12: Base case
B14: - | C14: INCOME STATEMENT | G14: FORECAST
C15: Fiscal year | D15: =E15-1 -> 2016 | E15: =F15-1 -> 2017 | F15: =YEAR($D$10) -> 2018 | G15: =F15+1 -> 2019 | H15: =G15+1 -> 2020 | I15: =H15+1 -> 2021 | J15: =I15+1 -> 2022 | K15: =J15+1 -> 2023 | M15: 5 year
C16: Fiscal year end date | D16: =EOMONTH(E16,-12) -> 43008 | E16: 43372 | F16: =$D$10 -> 43372 | G16: =EOMONTH(F16,12) -> 43738 | H16: =EOMONTH(G16,12) -> 44104 | I16: =EOMONTH(H16,12) -> 44469 | J16: =EOMONTH(I16,12) -> 44834 | K16: =EOMONTH(J16,12) -> 45199 | M16: CAGR | O16: WSP Comments
C18: Revenue | D18: 215639 | E18: 229234 | F18: 265595 | G18: =F18*(1+G37) -> 252990.48 | H18: =G18*(1+H37) -> 265376.78 | I18: =H18*(1+I37) -> 278407.76 | J18: =I18*(1+J37) -> 293588.36 | K18: =J18*(1+K37) -> 311276.69 | M18: =(K18/F18)^(1/COUNT(G18:K18))-1 -> 0.03225107 | O18: Previous year's revenues x (1+revenue growth rate)
C19: Cost of sales (enter as -) | D19: -131376 | E19: -141048 | F19: -163756 | G19: =G20-G18 -> -157360.08 | H19: =H20-H18 -> -164533.61 | I19: =I20-I18 -> -172056 | J19: =J20-J18 -> -181437.6 | K19: =K20-K18 -> -192369 | O19: Plug = Revenue - Gross Profit
C20: Gross Profit | D20: =SUM(D18:D19) -> 84263 | E20: =SUM(E18:E19) -> 88186 | F20: =SUM(F18:F19) -> 101839 | G20: =G18*G38 -> 95630.402 | H20: =H18*H38 -> 100843.18 | I20: =I18*I38 -> 106351.76 | J20: =J18*J38 -> 112150.75 | K20: =K18*K38 -> 118907.7 | O20: Revenue x Gross Profit Margin forecast
C21: Research & development (enter as -) | D21: -10045 | E21: -11581 | F21: -14236 | G21: =-G18*G39 -> -15685.41 | H21: =-H18*H39 -> -16718.737 | I21: =-I18*I39 -> -17539.689 | J21: =-J18*J39 -> -18496.066 | K21: =-K18*K39 -> -19610.432 | O21: Revenue x R&D % of sales forecast
C22: Selling, general & administrative (enter as -) | D22: -14194 | E22: -15261 | F22: -16705 | G22: =-G18*G40 -> -18721.296 | H22: =-H18*H40 -> -18310.998 | I22: =-I18*I40 -> -19210.135 | J22: =-J18*J40 -> -20257.597 | K22: =-K18*K40 -> -21478.092 | O22: Revenue x SG&A % of sales forecast
C23: Operating profit (EBIT) | D23: =SUM(D20:D22) -> 60024 | E23: =SUM(E20:E22) -> 61344 | F23: =SUM(F20:F22) -> 70898 | G23: =SUM(G20:G22) -> 61223.697 | H23: =SUM(H20:H22) -> 65813.442 | I23: =SUM(I20:I22) -> 69601.94 | J23: =SUM(J20:J22) -> 73397.089 | K23: =SUM(K20:K22) -> 77819.173 | M23: =(K23/F23)^(1/COUNT(G23:K23))-1 -> 0.018803728 | O23: Gross Profit - R&D - SG&A
C24: Interest income | D24: 3999 | E24: 5201 | F24: 5686 | G24: =G221 -> 4701.9145 | H24: =H221 -> 3950.7434 | I24: =I221 -> 3347.1994 | J24: =J221 -> 2820.748 | K24: =K221 -> 2385.0141 | O24: Reference from interest on cash schedule
C25: Interest expense (enter as -) | D25: -1456 | E25: -2323 | F25: -3240 | G25: =-G217-G212 -> -3223.1469 | H25: =-H217-H212 -> -3223.5393 | I25: =-I217-I212 -> -3223.5393 | J25: =-J217-J212 -> -3223.5393 | K25: =-K217-K212 -> -3223.5393 | O25: Reference from interest expense schedule
C26: Other expense, net (enter as -) | D26: -1195 | E26: -133 | F26: -441 | G26: =F26 -> -441 | H26: =G26 -> -441 | I26: =H26 -> -441 | J26: =I26 -> -441 | K26: =J26 -> -441 | O26: Straight-line
C27: Pretax profit | D27: =SUM(D23:D26) -> 61372 | E27: =SUM(E23:E26) -> 64089 | F27: =SUM(F23:F26) -> 72903 | G27: =SUM(G23:G26) -> 62261.464 | H27: =SUM(H23:H26) -> 66099.647 | I27: =SUM(I23:I26) -> 69284.6 | J27: =SUM(J23:J26) -> 72553.298 | K27: =SUM(K23:K26) -> 76539.648 | O27: EBIT + interest income less interest expense less other expense
C28: Taxes (enter expense as -) | D28: -15685 | E28: -15738 | F28: -13372 | G28: =-G27*G41 -> -10397.665 | H28: =-H27*H41 -> -11236.94 | I28: =-I27*I41 -> -11709.097 | J28: =-J27*J41 -> -12261.507 | K28: =-K27*K41 -> -12935.201 | O28: Pre-tax Profit x Tax Rate forecast
C29: Net income | D29: =SUM(D27:D28) -> 45687 | E29: =SUM(E27:E28) -> 48351 | F29: =SUM(F27:F28) -> 59531 | G29: =SUM(G27:G28) -> 51863.8 | H29: =SUM(H27:H28) -> 54862.707 | I29: =SUM(I27:I28) -> 57575.503 | J29: =SUM(J27:J28) -> 60291.791 | K29: =SUM(K27:K28) -> 63604.447 | M29: =(K29/F29)^(1/COUNT(G29:K29))-1 -> 0.013325242 | O29: Pre-tax Profit less taxes
B31: - | C31: Depreciation & amortization | D31: 10505 | E31: 10157 | F31: 10903 | G31: =G171 -> 9459.5504 | H31: =H171 -> 9672.433 | I31: =I171 -> 10302.456 | J31: =J171 -> 11333.642 | K31: =K171 -> 12710.209 | O31: Reference from D&A schedule
C32: EBITDA | D32: =D23+D31 -> 70529 | E32: =E23+E31 -> 71501 | F32: =F23+F31 -> 81801 | G32: =G23+G31 -> 70683.247 | H32: =H23+H31 -> 75485.875 | I32: =I23+I31 -> 79904.396 | J32: =J23+J31 -> 84730.731 | K32: =K23+K31 -> 90529.382 | M32: =(K32/F32)^(1/COUNT(G32:K32))-1 -> 0.020483975 | O32: EBIT + D&A
C33: Stock based compensation | D33: 4210 | E33: 4840 | F33: 5340 | G33: =F33*(1+G37) -> 5086.5761 | H33: =G33*(1+H37) -> 5335.6126 | I33: =H33*(1+I37) -> 5597.6108 | J33: =I33*(1+J37) -> 5902.8288 | K33: =J33*(1+K37) -> 6258.467 | O33: WSP assumption: grow SBC in-line with revenue growth
C34: Adjusted EBITDA | D34: =SUM(D32:D33) -> 74739 | E34: =SUM(E32:E33) -> 76341 | F34: =SUM(F32:F33) -> 87141 | G34: =SUM(G32:G33) -> 75769.823 | H34: =SUM(H32:H33) -> 80821.488 | I34: =SUM(I32:I33) -> 85502.007 | J34: =SUM(J32:J33) -> 90633.56 | K34: =SUM(K32:K33) -> 96787.849 | O34: EBITDA + Stock-based compensation
C36: Growth rates & margins
C37: Revenue growth | E37: =E18/D18-1 -> 0.063045182 | F37: =F18/E18-1 -> 0.15861958 | G37: ='Revenues build-up'!G14 -> -0.047457664 | H37: ='Revenues build-up'!H14 -> 0.048959559 | I37: ='Revenues build-up'!I14 -> 0.049103677 | J37: ='Revenues build-up'!J14 -> 0.054526487 | K37: ='Revenues build-up'!K14 -> 0.060248763 | O37: Scenario analysis schedule below
C38: Gross profit margin | D38: =D20/D18 -> 0.39075956 | E38: =E20/E18 -> 0.3846986 | F38: =F20/F18 -> 0.38343719 | G38: =G241 -> 0.378 | H38: =H241 -> 0.38 | I38: =I241 -> 0.382 | J38: =J241 -> 0.382 | K38: =K241 -> 0.382 | O38: Scenario analysis schedule below
C39: R&D % of sales | D39: =-D21/D18 -> 0.046582483 | E39: =-E21/E18 -> 0.050520429 | F39: =-F21/F18 -> 0.053600407 | G39: =G242 -> 0.062 | H39: =H242 -> 0.063 | I39: =I242 -> 0.063 | J39: =J242 -> 0.063 | K39: =K242 -> 0.063 | O39: Scenario analysis schedule below
C40: SG&A % of sales | D40: =-D22/D18 -> 0.065822973 | E40: =-E22/E18 -> 0.066573894 | F40: =-F22/F18 -> 0.062896515 | G40: =G243 -> 0.074 | H40: =H243 -> 0.069 | I40: =I243 -> 0.069 | J40: =J243 -> 0.069 | K40: =K243 -> 0.069 | O40: Scenario analysis schedule below
C41: Tax rate | D41: =-D28/D27 -> 0.25557257 | E41: =-E28/E27 -> 0.24556476 | F41: =-F28/F27 -> 0.18342181 | G41: 0.167 | H41: 0.17 | I41: 0.169 | J41: =I41 -> 0.169 | K41: =J41 -> 0.169 | O41: Straight line last historical year
B43: - | C43: BALANCE SHEET
C44: =C15 -> Fiscal year | E44: =E15 -> 2017 | F44: =F15 -> 2018 | G44: =G15 -> 2019 | H44: =H15 -> 2020 | I44: =I15 -> 2021 | J44: =J15 -> 2022 | K44: =K15 -> 2023
C45: =C16 -> Fiscal year end date | E45: =E16 -> 43372 | F45: =F16 -> 43372 | G45: =G16 -> 43738 | H45: =H16 -> 44104 | I45: =I16 -> 44469 | J45: =J16 -> 44834 | K45: =K16 -> 45199 | O45: B/S check
C46: Cash & equivalents, ST and LT marketable securities | E46: =20289+53892+194714 -> 268895 | F46: =25913+40388+170799 -> 237100 | G46: =F46+G92 -> 198262.46 | H46: =G46+H92 -> 167547.12 | I46: =H46+I92 -> 142378.75 | J46: =I46+J92 -> 118801.62 | K46: =J46+K92 -> 102033.02 | R46: Reference from 'net change in cash' line on the cash flow statement
C47: Accounts receivable | E47: 17874 | F47: 23186 | G47: =G101 -> 23946.473 | H47: =H101 -> 25493.585 | I47: =I101 -> 26374.162 | J47: =J101 -> 28321.751 | K47: =K101 -> 29669.523 | R47: Grow in-line with revenue growth
...

Sheet Revenues build-up
C2: Price / volume build | N2: Iphone asp
C3: Fiscal year | D3: 2016 | E3: 2017 | F3: 2018 | G3: 2019 | H3: 2020 | I3: 2021 | J3: 2022 | K3: 2023 | N3: Iphone units number
C4: Fiscal year end date | D4: 43008 | E4: 43372 | F4: 43372 | G4: 43738 | H4: 44104 | I4: 44469 | J4: 44834 | K4: 45199
C5: Revenue by product
C6: Core products:
C7: iPhone | D7: 136700 | E7: 141319 | F7: 166699 | G7: =G17*G22/1000 -> 137570.4 | H7: =H17*H22/1000 -> 138388 | I7: =I17*I22/1000 -> 138388 | J7: =J17*J22/1000 -> 138388 | K7: =K17*K22/1000 -> 138388
C8: iPad | D8: 20628 | E8: 19222 | F8: 18805 | G8: =G18*G23/1000 -> 20222.922 | H8: =H18*H23/1000 -> 20475.904 | I8: =I18*I23/1000 -> 20475.904 | J8: =J18*J23/1000 -> 20475.904 | K8: =K18*K23/1000 -> 20475.904
C9: Mac | D9: 22831 | E9: 25850 | F9: 25484 | G9: =G19*G24/1000 -> 26515.16 | H9: =H19*H24/1000 -> 26642.88 | I9: =I19*I24/1000 -> 26642.88 | J9: =J19*J24/1000 -> 26642.88 | K9: =K19*K24/1000 -> 26642.88
C11: Services | D11: 24348 | E11: 29980 | F11: 37190 | G11: 45603 | H11: 53592 | I11: =H11*(1+I40) -> 62980.56 | J11: =I11*(1+J40) -> 74013.862 | K11: =J11*(1+K40) -> 86980.043 | M11: CG estimates through 2020; WSP thereafter
C12: Other products | D12: 11132 | E12: 12863 | F12: 17417 | G12: 23079 | H12: 26278 | I12: =H12*(1+I41) -> 29920.416 | J12: =I12*(1+J41) -> 34067.711 | K12: =J12*(1+K41) -> 38789.865 | M12: CG estimates through 2020; WSP thereafter
C13: Total revenue | D13: =SUM(D7:D9,D11:D12) -> 215639 | E13: =SUM(E7:E9,E11:E12) -> 229234 | F13: =SUM(F7:F9,F11:F12) -> 265595 | G13: =SUM(G7:G9,G11:G12) -> 252990.48 | H13: =SUM(H7:H9,H11:H12) -> 265376.78 | I13: =SUM(I7:I9,I11:I12) -> 278407.76 | J13: =SUM(J7:J9,J11:J12) -> 293588.36 | K13: =SUM(K7:K9,K11:K12) -> 311276.69
C14: % growth | E14: =E13/D13-1 -> 0.063045182 | F14: =F13/E13-1 -> 0.15861958 | G14: =G13/F13-1 -> -0.047457664 | H14: =H13/G13-1 -> 0.048959559 | I14: =I13/H13-1 -> 0.049103677 | J14: =J13/I13-1 -> 0.054526487 | K14: =K13/J13-1 -> 0.060248763
C16: Units
C17: iPhone | D17: 211884 | E17: 216756 | F17: 217722 | G17: ='3-statement model'!G239 -> 173700 | H17: ='3-statement model'!H239 -> 190880 | I17: ='3-statement model'!I239 -> 190880 | J17: ='3-statement model'!J239 -> 190880 | K17: ='3-statement model'!K239 -> 190880 | M17: CG estimates through 2020; straight line thereafter
C18: iPad | D18: 45590 | E18: 43753 | F18: 43535 | G18: 46170 | H18: 49260 | I18: =H18 -> 49260 | J18: =I18 -> 49260 | K18: =J18 -> 49260 | M18: CG estimates through 2020; straight line thereafter
C19: Mac | D19: 18484 | E19: 19251 | F19: 18209 | G19: 19670 | H19: 19140 | I19: =H19 -> 19140 | J19: =I19 -> 19140 | K19: =J19 -> 19140 | M19: CG estimates through 2020; straight line thereafter
C21: Average selling price
C22: iPhone | D22: =1000*D7/D17 -> 645.16434 | E22: =1000*E7/E17 -> 651.97273 | F22: =1000*F7/F17 -> 765.65069 | G22: ='3-statement model'!G240 -> 792 | H22: ='3-statement model'!H240 -> 725 | I22: ='3-statement model'!I240 -> 725 | J22: ='3-statement model'!J240 -> 725 | K22: ='3-statement model'!K240 -> 725 | M22: CG estimates through 2020; straight line thereafter
C23: iPad | D23: =1000*D8/D18 -> 452.46765 | E23: =1000*E8/E18 -> 439.32987 | F23: =1000*F8/F18 -> 431.9513 | G23: 438.01 | H23: 415.67 | I23: =H23 -> 415.67 | J23: =I23 -> 415.67 | K23: =J23 -> 415.67 | M23: CG estimates through 2020; straight line thereafter
C24: Mac | D24: =1000*D9/D19 -> 1235.1764 | E24: =1000*E9/E19 -> 1342.7874 | F24: =1000*F9/F19 -> 1399.5277 | G24: 1348 | H24: 1392 | I24: =H24 -> 1392 | J24: =I24 -> 1392 | K24: =J24 -> 1392 | M24: CG estimates through 2020; straight line thereafter
C26: Units % growth
C27: iPhone | E27: =E17/D17-1 -> 0.022993714 | F27: =F17/E17-1 -> 0.004456624 | G27: =G17/F17-1 -> -0.20219362 | H27: =H17/G17-1 -> 0.09890616 | I27: =I17/H17-1 -> 0 | J27: =J17/I17-1 -> 0 | K27: =K17/J17-1 -> 0
C28: iPad | E28: =E18/D18-1 -> -0.040293924 | F28: =F18/E18-1 -> -0.0049825155 | G28: =G18/F18-1 -> 0.060526014 | H28: =H18/G18-1 -> 0.066926576 | I28: =I18/H18-1 -> 0 | J28: =J18/I18-1 -> 0 | K28: =K18/J18-1 -> 0
C29: Mac | E29: =E19/D19-1 -> 0.041495347 | F29: =F19/E19-1 -> -0.054127058 | G29: =G19/F19-1 -> 0.080235049 | H29: =H19/G19-1 -> -0.026944586 | I29: =I19/H19-1 -> 0 | J29: =J19/I19-1 -> 0 | K29: =K19/J19-1 -> 0
C31: Average selling price % growth
C32: iPhone | E32: =E22/D22-1 -> 0.010552955 | F32: =F22/E22-1 -> 0.17436 | G32: =G22/F22-1 -> 0.034414268 | H32: =H22/G22-1 -> -0.08459596 | I32: =I22/H22-1 -> 0 | J32: =J22/I22-1 -> 0 | K32: =K22/J22-1 -> 0
C33: iPad | E33: =E23/D23-1 -> -0.029035826 | F33: =F23/E23-1 -> -0.016795059 | G33: =G23/F23-1 -> 0.014026341 | H33: =H23/G23-1 -> -0.051003402 | I33: =I23/H23-1 -> 0 | J33: =J23/I23-1 -> 0 | K33: =K23/J23-1 -> 0
C34: Mac | E34: =E24/D24-1 -> 0.087121986 | F34: =F24/E24-1 -> 0.042255624 | G34: =G24/F24-1 -> -0.036817925 | H34: =H24/G24-1 -> 0.03264095 | I34: =I24/H24-1 -> 0 | J34: =J24/I24-1 -> 0 | K34: =K24/J24-1 -> 0
C36: Revenue growth rate by product
C37: iPhone | E37: =E7/D7-1 -> 0.03378932 | F37: =F7/E7-1 -> 0.17959369 | G37: =G7/F7-1 -> -0.1747377 | H37: =H7/G7-1 -> 0.0059431389 | I37: =I7/H7-1 -> 0 | J37: =J7/I7-1 -> 0 | K37: =K7/J7-1 -> 0
C38: iPad | E38: =E8/D8-1 -> -0.068159783 | F38: =F8/E8-1 -> -0.021693892 | G38: =G8/F8-1 -> 0.075401313 | H38: =H8/G8-1 -> 0.012509691 | I38: =I8/H8-1 -> 0 | J38: =J8/I8-1 -> 0 | K38: =K8/J8-1 -> 0
C39: Mac | E39: =E9/D9-1 -> 0.13223249 | F39: =F9/E9-1 -> -0.014158607 | G39: =G9/F9-1 -> 0.040463036 | H39: =H9/G9-1 -> 0.004816867 | I39: =I9/H9-1 -> 0 | J39: =J9/I9-1 -> 0 | K39: =K9/J9-1 -> 0
C40: Services | E40: =E11/D11-1 -> 0.23131263 | F40: =F11/E11-1 -> 0.24049366 | G40: =G11/F11-1 -> 0.22621672 | H40: =H11/G11-1 -> 0.17518584 | I40: =H40 -> 0.17518584 | J40: =I40 -> 0.17518584 | K40: =J40 -> 0.17518584
C41: Other products | E41: =E12/D12-1 -> 0.15549766 | F41: =F12/E12-1 -> 0.35403872 | G41: =G12/F12-1 -> 0.32508469 | H41: =H12/G12-1 -> 0.13861086 | I41: =H41 -> 0.13861086 | J41: =I41 -> 0.13861086 | K41: =J41 -> 0.13861086

Sheet FSM-2019 update
C2: ="Financial Statement Model for "&D5 -> Financial Statement Model for Apple
C3: $ and shares in millions, except per share data
C5: Company name | D5: Apple
C6: Ticker | D6: AAPL
C7: Circ break 1=off, 0=on | D7: 1
C8: Latest closing share price
C9: Latest closing share price date
C10: Latest fiscal year end date | D10: 43737
C11: Shares outstanding (millions)
C12: Select an operating scenario: | D12: Base case
B14: - | C14: INCOME STATEMENT | H14: FORECAST
C15: Fiscal year | D15: =E15-1 -> 2016 | E15: =F15-1 -> 2017 | F15: =G15-1 -> 2018 | G15: =YEAR($D$10) -> 2019 | H15: =G15+1 -> 2020 | I15: =H15+1 -> 2021 | J15: =I15+1 -> 2022 | K15: =J15+1 -> 2023 | L15: =K15+1 -> 2024 | N15: 5 year
C16: Fiscal year end date | D16: =EOMONTH(E16,-12) -> 42643 | E16: =EOMONTH(F16,-12) -> 43008 | F16: =EOMONTH(G16,-12) -> 43373 | G16: =$D$10 -> 43737 | H16: =EOMONTH(G16,12) -> 44104 | I16: =EOMONTH(H16,12) -> 44469 | J16: =EOMONTH(I16,12) -> 44834 | K16: =EOMONTH(J16,12) -> 45199 | L16: =EOMONTH(K16,12) -> 45565 | N16: CAGR | P16: WSP Comments
C18: Revenue | D18: 215639 | E18: 229234 | F18: 265595 | G18: 260174 | H18: =G18*(1+H37) -> 252990.48 | I18: =H18*(1+I37) -> 265376.78 | J18: =I18*(1+J37) -> 278407.76 | K18: =J18*(1+K37) -> 293588.36 | L18: =K18*(1+L37) -> 311276.69 | N18: =(L18/G18)^(1/COUNT(H18:L18))-1 -> 0.036517268 | P18: Previous year's revenues x (1+revenue growth rate)
C19: Cost of sales (enter as -) | D19: -131376 | E19: -141048 | F19: -163756 | G19: -161782 | H19: =H20-H18 -> -157360.08 | I19: =I20-I18 -> -164533.61 | J19: =J20-J18 -> -172056 | K19: =K20-K18 -> -181437.6 | L19: =L20-L18 -> -192369 | P19: Plug = Revenue - Gross Profit
C20: Gross Profit | D20: =SUM(D18:D19) -> 84263 | E20: =SUM(E18:E19) -> 88186 | F20: =SUM(F18:F19) -> 101839 | G20: =SUM(G18:G19) -> 98392 | H20: =H18*H38 -> 95630.402 | I20: =I18*I38 -> 100843.18 | J20: =J18*J38 -> 106351.76 | K20: =K18*K38 -> 112150.75 | L20: =L18*L38 -> 118907.7 | P20: Revenue x Gross Profit Margin forecast
C21: Research & development (enter as -) | D21: -10045 | E21: -11581 | F21: -14236 | G21: -16217 | H21: =-H18*H39 -> -15685.41 | I21: =-I18*I39 -> -16718.737 | J21: =-J18*J39 -> -17539.689 | K21: =-K18*K39 -> -18496.066 | L21: =-L18*L39 -> -19610.432 | P21: Revenue x R&D % of sales forecast
C22: Selling, general & administrative (enter as -) | D22: -14194 | E22: -15261 | F22: -16705 | G22: -18245 | H22: =-H18*H40 -> -18721.296 | I22: =-I18*I40 -> -18310.998 | J22: =-J18*J40 -> -19210.135 | K22: =-K18*K40 -> -20257.597 | L22: =-L18*L40 -> -21478.092 | P22: Revenue x SG&A % of sales forecast
C23: Operating profit (EBIT) | D23: =SUM(D20:D22) -> 60024 | E23: =SUM(E20:E22) -> 61344 | F23: =SUM(F20:F22) -> 70898 | G23: =SUM(G20:G22) -> 63930 | H23: =SUM(H20:H22) -> 61223.697 | I23: =SUM(I20:I22) -> 65813.442 | J23: =SUM(J20:J22) -> 69601.94 | K23: =SUM(K20:K22) -> 73397.089 | L23: =SUM(L20:L22) -> 77819.173 | N23: =(L23/G23)^(1/COUNT(H23:L23))-1 -> 0.040103078 | P23: Gross Profit - R&D - SG&A
C24: Interest income | D24: 3999 | E24: 5201 | F24: 5686 | G24: 4961 | H24: =H221 -> 4231.5591 | I24: =I221 -> 3685.6987 | J24: =J221 -> 3209.0879 | K24: =K221 -> 2818.3337 | L24: =L221 -> 2527.729 | P24: Reference from interest on cash schedule
C25: Interest expense (enter as -) | D25: -1456 | E25: -2323 | F25: -3240 | G25: -3576 | H25: =-H217-H212 -> -3568.9466 | I25: =-I217-I212 -> -3636.3706 | J25: =-J217-J212 -> -3636.3706 | K25: =-K217-K212 -> -3636.3706 | L25: =-L217-L212 -> -3636.3706 | P25: Reference from interest expense schedule
C26: Other expense, net (enter as -) | D26: -1195 | E26: -133 | F26: -441 | G26: 422 | H26: =G26 -> 422 | I26: =H26 -> 422 | J26: =I26 -> 422 | K26: =J26 -> 422 | L26: =K26 -> 422 | P26: Straight-line
C27: Pretax profit | D27: =SUM(D23:D26) -> 61372 | E27: =SUM(E23:E26) -> 64089 | F27: =SUM(F23:F26) -> 72903 | G27: =SUM(G23:G26) -> 65737 | H27: =SUM(H23:H26) -> 62308.309 | I27: =SUM(I23:I26) -> 66284.771 | J27: =SUM(J23:J26) -> 69596.657 | K27: =SUM(K23:K26) -> 73001.052 | L27: =SUM(L23:L26) -> 77132.531 | P27: EBIT + interest income less interest expense less other expense
C28: Taxes (enter expense as -) | D28: -15685 | E28: -15738 | F28: -13372 | G28: -10481 | H28: =-H27*H41 -> -10405.488 | I28: =-I27*I41 -> -11268.411 | J28: =-J27*J41 -> -11761.835 | K28: =-K27*K41 -> -12337.178 | L28: =-L27*L41 -> -13035.398 | P28: Pre-tax Profit x Tax Rate forecast
C29: Net income | D29: =SUM(D27:D28) -> 45687 | E29: =SUM(E27:E28) -> 48351 | F29: =SUM(F27:F28) -> 59531 | G29: =SUM(G27:G28) -> 55256 | H29: =SUM(H27:H28) -> 51902.821 | I29: =SUM(I27:I28) -> 55016.36 | J29: =SUM(J27:J28) -> 57834.822 | K29: =SUM(K27:K28) -> 60663.874 | L29: =SUM(L27:L28) -> 64097.134 | N29: =(L29/G29)^(1/COUNT(H29:L29))-1 -> 0.030129521 | P29: Pre-tax Profit less taxes
B31: - | C31: Depreciation & amortization | D31: 10505 | E31: 10157 | F31: 10903 | G31: 12547 | H31: =H171 -> 8908.4269 | I31: =I171 -> 9261.0795 | J31: =J171 -> 10114.414 | K31: =K171 -> 11423.77 | L31: =L171 -> 13112.053 | P31: Reference from D&A schedule
C32: EBITDA | D32: =D23+D31 -> 70529 | E32: =E23+E31 -> 71501 | F32: =F23+F31 -> 81801 | G32: =G23+G31 -> 76477 | H32: =H23+H31 -> 70132.123 | I32: =I23+I31 -> 75074.522 | J32: =J23+J31 -> 79716.354 | K32: =K23+K31 -> 84820.859 | L32: =L23+L31 -> 90931.227 | N32: =(L32/G32)^(1/COUNT(H32:L32))-1 -> 0.035229028 | P32: EBIT + D&A
C33: Stock based compensation | D33: 4210 | E33: 4840 | F33: 5340 | G33: 6068 | H33: =G33*(1+H37) -> 5900.4599 | I33: =H33*(1+I37) -> 6189.3438 | J33: =I33*(1+J37) -> 6493.2633 | K33: =J33*(1+K37) -> 6847.3181 | L33: =K33*(1+L37) -> 7259.8606 | P33: WSP assumption: grow SBC in-line with revenue growth
C34: Adjusted EBITDA | D34: =SUM(D32:D33) -> 74739 | E34: =SUM(E32:E33) -> 76341 | F34: =SUM(F32:F33) -> 87141 | G34: =SUM(G32:G33) -> 82545 | H34: =SUM(H32:H33) -> 76032.583 | I34: =SUM(I32:I33) -> 81263.866 | J34: =SUM(J32:J33) -> 86209.617 | K34: =SUM(K32:K33) -> 91668.177 | L34: =SUM(L32:L33) -> 98191.087 | P34: EBITDA + Stock-based compensation
C36: Growth rates & margins
C37: Revenue growth | E37: =E18/D18-1 -> 0.063045182 | F37: =F18/E18-1 -> 0.15861958 | G37: =G18/F18-1 -> -0.020410776 | H37: ='Rev-2019 update'!H14 -> -0.027610439 | I37: ='Rev-2019 update'!I14 -> 0.048959559 | J37: ='Rev-2019 update'!J14 -> 0.049103677 | K37: ='Rev-2019 update'!K14 -> 0.054526487 | L37: ='Rev-2019 update'!L14 -> 0.060248763 | P37: Scenario analysis schedule below
C38: Gross profit margin | D38: =D20/D18 -> 0.39075956 | E38: =E20/E18 -> 0.3846986 | F38: =F20/F18 -> 0.38343719 | G38: =G20/G18 -> 0.37817768 | H38: =H241 -> 0.378 | I38: =I241 -> 0.38 | J38: =J241 -> 0.382 | K38: =K241 -> 0.382 | L38: =L241 -> 0.382 | P38: Scenario analysis schedule below
C39: R&D % of sales | D39: =-D21/D18 -> 0.046582483 | E39: =-E21/E18 -> 0.050520429 | F39: =-F21/F18 -> 0.053600407 | G39: =-G21/G18 -> 0.062331363 | H39: =H242 -> 0.062 | I39: =I242 -> 0.063 | J39: =J242 -> 0.063 | K39: =K242 -> 0.063 | L39: =L242 -> 0.063 | P39: Scenario analysis schedule below
C40: SG&A % of sales | D40: =-D22/D18 -> 0.065822973 | E40: =-E22/E18 -> 0.066573894 | F40: =-F22/F18 -> 0.062896515 | G40: =-G22/G18 -> 0.070126146 | H40: =H243 -> 0.074 | I40: =I243 -> 0.069 | J40: =J243 -> 0.069 | K40: =K243 -> 0.069 | L40: =L243 -> 0.069 | P40: Scenario analysis schedule below
C41: Tax rate | D41: =-D28/D27 -> 0.25557257 | E41: =-E28/E27 -> 0.24556476 | F41: =-F28/F27 -> 0.18342181 | G41: =-G28/G27 -> 0.15943837 | H41: 0.167 | I41: 0.17 | J41: 0.169 | K41: =J41 -> 0.169 | L41: =K41 -> 0.169 | P41: Straight line last historical year
B43: - | C43: BALANCE SHEET
C44: =C15 -> Fiscal year | E44: =E15 -> 2017 | F44: =F15 -> 2018 | G44: =G15 -> 2019 | H44: =H15 -> 2020 | I44: =I15 -> 2021 | J44: =J15 -> 2022 | K44: =K15 -> 2023 | L44: =L15 -> 2024
C45: =C16 -> Fiscal year end date | E45: =E16 -> 43008 | F45: =F16 -> 43373 | G45: =G16 -> 43737 | H45: =H16 -> 44104 | I45: =I16 -> 44469 | J45: =J16 -> 44834 | K45: =K16 -> 45199 | L45: =L16 -> 45565
C46: Cash & equivalents, ST and LT marketable securities | E46: =20289+53892+194714 -> 268895 | F46: =25913+40388+170799 -> 237100 | G46: =48844+51713+105341 -> 205898 | H46: =G46+H92 -> 180545.75 | I46: =H46+I92 -> 156047.73 | J46: =I46+J92 -> 137019.66 | K46: =J46+K92 -> 120362.41 | L46: =K46+L92 -> 110480.41 | P46: Reference from 'net change in cash' line on the cash flow statement
C47: Accounts receivable | E47: 17874 | F47: 23186 | G47: 22926 | H47: =H101 -> 24206.473 | I47: =I101 -> 25233.585 | J47: =J101 -> 26634.162 | K47: =K101 -> 28061.751 | L47: =L101 -> 29929.523 | P47: Grow in-line with revenue growth
...

Sheet Rev-2019 update
C2: Price / volume build | O2: Iphone asp
C3: Fiscal year | D3: =E3-1 -> 2016 | E3: =F3-1 -> 2017 | F3: =G3-1 -> 2018 | G3: =YEAR('FSM-2019 update'!D10) -> 2019 | H3: =G3+1 -> 2020 | I3: =H3+1 -> 2021 | J3: =I3+1 -> 2022 | K3: =J3+1 -> 2023 | L3: =K3+1 -> 2024 | O3: Iphone units number
C4: Fiscal year end date | D4: =EOMONTH(E4,-12) -> 42643 | E4: =EOMONTH(F4,-12) -> 43008 | F4: =EOMONTH(G4,-12) -> 43373 | G4: ='FSM-2019 update'!D10 -> 43737 | H4: =EOMONTH(G4,12) -> 44104 | I4: =EOMONTH(H4,12) -> 44469 | J4: =EOMONTH(I4,12) -> 44834 | K4: =EOMONTH(J4,12) -> 45199 | L4: =EOMONTH(K4,12) -> 45565
C5: Revenue by product
C6: Core products:
C7: iPhone | D7: 136700 | E7: 141319 | F7: 166699 | G7: 142381 | H7: =H17*H22/1000 -> 137570.4 | I7: =I17*I22/1000 -> 138388 | J7: =J17*J22/1000 -> 138388 | K7: =K17*K22/1000 -> 138388 | L7: =L17*L22/1000 -> 138388
C8: iPad | D8: 20628 | E8: 19222 | F8: 18805 | G8: 21280 | H8: =H18*H23/1000 -> 20222.922 | I8: =I18*I23/1000 -> 20475.904 | J8: =J18*J23/1000 -> 20475.904 | K8: =K18*K23/1000 -> 20475.904 | L8: =L18*L23/1000 -> 20475.904
C9: Mac | D9: 22831 | E9: 25850 | F9: 25484 | G9: 25740 | H9: =H19*H24/1000 -> 26515.16 | I9: =I19*I24/1000 -> 26642.88 | J9: =J19*J24/1000 -> 26642.88 | K9: =K19*K24/1000 -> 26642.88 | L9: =L19*L24/1000 -> 26642.88
C11: Services | D11: 24348 | E11: 29980 | F11: 37190 | G11: 46291 | H11: 45603 | I11: 53592 | J11: =I11*(1+J40) -> 62980.56 | K11: =J11*(1+K40) -> 74013.862 | L11: =K11*(1+L40) -> 86980.043 | N11: CG estimates through 2020; WSP thereafter
C12: Other products | D12: 11132 | E12: 12863 | F12: 17417 | G12: 24482 | H12: 23079 | I12: 26278 | J12: =I12*(1+J41) -> 29920.416 | K12: =J12*(1+K41) -> 34067.711 | L12: =K12*(1+L41) -> 38789.865 | N12: CG estimates through 2020; WSP thereafter
C13: Total revenue | D13: =SUM(D7:D9,D11:D12) -> 215639 | E13: =SUM(E7:E9,E11:E12) -> 229234 | F13: =SUM(F7:F9,F11:F12) -> 265595 | G13: =SUM(G7:G9,G11:G12) -> 260174 | H13: =SUM(H7:H9,H11:H12) -> 252990.48 | I13: =SUM(I7:I9,I11:I12) -> 265376.78 | J13: =SUM(J7:J9,J11:J12) -> 278407.76 | K13: =SUM(K7:K9,K11:K12) -> 293588.36 | L13: =SUM(L7:L9,L11:L12) -> 311276.69
C14: % growth | E14: =E13/D13-1 -> 0.063045182 | F14: =F13/E13-1 -> 0.15861958 | G14: =G13/F13-1 -> -0.020410776 | H14: =H13/G13-1 -> -0.027610439 | I14: =I13/H13-1 -> 0.048959559 | J14: =J13/I13-1 -> 0.049103677 | K14: =K13/J13-1 -> 0.054526487 | L14: =L13/K13-1 -> 0.060248763
C16: Units
C17: iPhone | D17: 211884 | E17: 216756 | F17: 217722 | G17: 191000 | H17: ='FSM-2019 update'!H239 -> 173700 | I17: ='FSM-2019 update'!I239 -> 190880 | J17: ='FSM-2019 update'!J239 -> 190880 | K17: ='FSM-2019 update'!K239 -> 190880 | L17: ='FSM-2019 update'!L239 -> 190880 | N17: CG estimates through 2020; straight line thereafter
C18: iPad | D18: 45590 | E18: 43753 | F18: 43535 | G18: 49900 | H18: 46170 | I18: 49260 | J18: =I18 -> 49260 | K18: =J18 -> 49260 | L18: =K18 -> 49260 | N18: CG estimates through 2020; straight line thereafter
C19: Mac | D19: 18484 | E19: 19251 | F19: 18209 | G19: 17500 | H19: 19670 | I19: 19140 | J19: =I19 -> 19140 | K19: =J19 -> 19140 | L19: =K19 -> 19140 | N19: CG estimates through 2020; straight line thereafter
C21: Average selling price
C22: iPhone | D22: =1000*D7/D17 -> 645.16434 | E22: =1000*E7/E17 -> 651.97273 | F22: =1000*F7/F17 -> 765.65069 | G22: =1000*G7/G17 -> 745.45026 | H22: ='FSM-2019 update'!H240 -> 792 | I22: ='FSM-2019 update'!I240 -> 725 | J22: ='FSM-2019 update'!J240 -> 725 | K22: ='FSM-2019 update'!K240 -> 725 | L22: ='FSM-2019 update'!L240 -> 725 | N22: CG estimates through 2020; straight line thereafter
C23: iPad | D23: =1000*D8/D18 -> 452.46765 | E23: =1000*E8/E18 -> 439.32987 | F23: =1000*F8/F18 -> 431.9513 | G23: =1000*G8/G18 -> 426.45291 | H23: 438.01 | I23: 415.67 | J23: =I23 -> 415.67 | K23: =J23 -> 415.67 | L23: =K23 -> 415.67 | N23: CG estimates through 2020; straight line thereafter
C24: Mac | D24: =1000*D9/D19 -> 1235.1764 | E24: =1000*E9/E19 -> 1342.7874 | F24: =1000*F9/F19 -> 1399.5277 | G24: =1000*G9/G19 -> 1470.8571 | H24: 1348 | I24: 1392 | J24: =I24 -> 1392 | K24: =J24 -> 1392 | L24: =K24 -> 1392 | N24: CG estimates through 2020; straight line thereafter
C26: Units % growth
C27: iPhone | E27: =E17/D17-1 -> 0.022993714 | F27: =F17/E17-1 -> 0.004456624 | G27: =G17/F17-1 -> -0.1227345 | H27: =H17/G17-1 -> -0.090575916 | I27: =I17/H17-1 -> 0.09890616 | J27: =J17/I17-1 -> 0 | K27: =K17/J17-1 -> 0 | L27: =L17/K17-1 -> 0
C28: iPad | E28: =E18/D18-1 -> -0.040293924 | F28: =F18/E18-1 -> -0.0049825155 | G28: =G18/F18-1 -> 0.1462042 | H28: =H18/G18-1 -> -0.074749499 | I28: =I18/H18-1 -> 0.066926576 | J28: =J18/I18-1 -> 0 | K28: =K18/J18-1 -> 0 | L28: =L18/K18-1 -> 0
C29: Mac | E29: =E19/D19-1 -> 0.041495347 | F29: =F19/E19-1 -> -0.054127058 | G29: =G19/F19-1 -> -0.038936789 | H29: =H19/G19-1 -> 0.124 | I29: =I19/H19-1 -> -0.026944586 | J29: =J19/I19-1 -> 0 | K29: =K19/J19-1 -> 0 | L29: =L19/K19-1 -> 0
C31: Average selling price % growth
C32: iPhone | E32: =E22/D22-1 -> 0.010552955 | F32: =F22/E22-1 -> 0.17436 | G32: =G22/F22-1 -> -0.02638335 | H32: =H22/G22-1 -> 0.06244513 | I32: =I22/H22-1 -> -0.08459596 | J32: =J22/I22-1 -> 0 | K32: =K22/J22-1 -> 0 | L32: =L22/K22-1 -> 0
C33: iPad | E33: =E23/D23-1 -> -0.029035826 | F33: =F23/E23-1 -> -0.016795059 | G33: =G23/F23-1 -> -0.012729207 | H33: =H23/G23-1 -> 0.027100517 | I33: =I23/H23-1 -> -0.051003402 | J33: =J23/I23-1 -> 0 | K33: =K23/J23-1 -> 0 | L33: =L23/K23-1 -> 0
C34: Mac | E34: =E24/D24-1 -> 0.087121986 | F34: =F24/E24-1 -> 0.042255624 | G34: =G24/F24-1 -> 0.050966791 | H34: =H24/G24-1 -> -0.083527584 | I34: =I24/H24-1 -> 0.03264095 | J34: =J24/I24-1 -> 0 | K34: =K24/J24-1 -> 0 | L34: =L24/K24-1 -> 0
C36: Revenue growth rate by product
C37: iPhone | E37: =E7/D7-1 -> 0.03378932 | F37: =F7/E7-1 -> 0.17959369 | G37: =G7/F7-1 -> -0.1458797 | H37: =H7/G7-1 -> -0.033786811 | I37: =I7/H7-1 -> 0.0059431389 | J37: =J7/I7-1 -> 0 | K37: =K7/J7-1 -> 0 | L37: =L7/K7-1 -> 0
C38: iPad | E38: =E8/D8-1 -> -0.068159783 | F38: =F8/E8-1 -> -0.021693892 | G38: =G8/F8-1 -> 0.13161393 | H38: =H8/G8-1 -> -0.049674732 | I38: =I8/H8-1 -> 0.012509691 | J38: =J8/I8-1 -> 0 | K38: =K8/J8-1 -> 0 | L38: =L8/K8-1 -> 0
C39: Mac | E39: =E9/D9-1 -> 0.13223249 | F39: =F9/E9-1 -> -0.014158607 | G39: =G9/F9-1 -> 0.010045519 | H39: =H9/G9-1 -> 0.030114996 | I39: =I9/H9-1 -> 0.004816867 | J39: =J9/I9-1 -> 0 | K39: =K9/J9-1 -> 0 | L39: =L9/K9-1 -> 0
C40: Services | E40: =E11/D11-1 -> 0.23131263 | F40: =F11/E11-1 -> 0.24049366 | G40: =G11/F11-1 -> 0.24471632 | H40: =H11/G11-1 -> -0.0148625 | I40: =I11/H11-1 -> 0.17518584 | J40: =I40 -> 0.17518584 | K40: =J40 -> 0.17518584 | L40: =K40 -> 0.17518584
C41: Other products | E41: =E12/D12-1 -> 0.15549766 | F41: =F12/E12-1 -> 0.35403872 | G41: =G12/F12-1 -> 0.40563817 | H41: =H12/G12-1 -> -0.05730741 | I41: =I12/H12-1 -> 0.13861086 | J41: =I41 -> 0.13861086 | K41: =J41 -> 0.13861086 | L41: =K41 -> 0.13861086
